DEBUG 2018-08-17 20:20:58,779: 	 Executing command: 'submit'
DEBUG 2018-08-17 20:20:58,779: 	 Found CRAB cache file /afs/cern.ch/user/p/psiddire/.crab3
DEBUG 2018-08-17 20:20:58,787: 	 Checking credentials
DEBUG 2018-08-17 20:20:58,788: 	 Found proxy file /tmp/x509up_u93494
DEBUG 2018-08-17 20:20:58,788: 	 Getting proxy life time left
DEBUG 2018-08-17 20:20:59,609: 	 Executing : 
 command : voms-proxy-info -file /tmp/x509up_u93494 -timeleft
 output : 42473

 error: 
 retcode : 0
DEBUG 2018-08-17 20:21:00,719: 	 Executing : 
 command : voms-proxy-info -file /tmp/x509up_u93494 -actimeleft
 output : 42470

 error: 
 retcode : 0
DEBUG 2018-08-17 20:21:00,720: 	 Proxy valid for 11:47:53 hours
INFO 2018-08-17 20:21:00,720: 	 Will use CRAB configuration file crab_Wm.py
DEBUG 2018-08-17 20:21:00,720: 	 Loading CRAB configuration file.
DEBUG 2018-08-17 20:21:05,121: 	 Will use CRAB Analysis plugin (i.e. will run an analysis job type).
ERROR 2018-08-17 20:21:05,122: 	 Working area '/afs/cern.ch/user/p/psiddire/CMSSW_9_4_8/src/pileup/PileupAnalyzer/test/crab_projects/crab_plots_PileupAnalyzer_Wm' already exists 
Please change the requestName in the config file
ERROR 2018-08-17 20:21:05,122: 	 Caught exception
Traceback (most recent call last):
  File "/cvmfs/cms.cern.ch/crab3/slc6_amd64_gcc493/cms/crabclient/3.3.1805.patch1/bin/crab", line 160, in <module>
    client()
  File "/cvmfs/cms.cern.ch/crab3/slc6_amd64_gcc493/cms/crabclient/3.3.1805.patch1/bin/crab", line 146, in __call__
    self.cmd = sub_cmd(self.logger, args[1:])
  File "/cvmfs/cms.cern.ch/crab3/slc6_amd64_gcc493/cms/crabclient/3.3.1805.patch1/lib/python2.7/site-packages/CRABClient/Commands/submit.py", line 34, in __init__
    SubCommand.__init__(self, logger, cmdargs, disable_interspersed_args=True)
  File "/cvmfs/cms.cern.ch/crab3/slc6_amd64_gcc493/cms/crabclient/3.3.1805.patch1/lib/python2.7/site-packages/CRABClient/Commands/SubCommand.py", line 307, in __init__
    getattr(self.configuration.General, 'requestName', None))
  File "/cvmfs/cms.cern.ch/crab3/slc6_amd64_gcc493/cms/crabclient/3.3.1805.patch1/lib/python2.7/site-packages/CRABClient/ClientUtilities.py", line 404, in createWorkArea
    raise ConfigException("Working area '%s' already exists \nPlease change the requestName in the config file" % fullpath)
ConfigException: Working area '/afs/cern.ch/user/p/psiddire/CMSSW_9_4_8/src/pileup/PileupAnalyzer/test/crab_projects/crab_plots_PileupAnalyzer_Wm' already exists 
Please change the requestName in the config file
DEBUG 2018-08-18 18:02:53,850: 	 Executing command: 'status'
DEBUG 2018-08-18 18:02:53,850: 	 Found CRAB cache file /afs/cern.ch/user/p/psiddire/.crab3
ERROR 2018-08-18 18:02:53,852: 	 Error: crab_plots_PileupAnalyzer_DY1 is not a valid CRAB project directory.
ERROR 2018-08-18 18:02:53,852: 	 Caught exception
Traceback (most recent call last):
  File "/cvmfs/cms.cern.ch/crab3/slc6_amd64_gcc493/cms/crabclient/3.3.1805.patch1/bin/crab", line 160, in <module>
    client()
  File "/cvmfs/cms.cern.ch/crab3/slc6_amd64_gcc493/cms/crabclient/3.3.1805.patch1/bin/crab", line 146, in __call__
    self.cmd = sub_cmd(self.logger, args[1:])
  File "/cvmfs/cms.cern.ch/crab3/slc6_amd64_gcc493/cms/crabclient/3.3.1805.patch1/lib/python2.7/site-packages/CRABClient/Commands/status.py", line 39, in __init__
    SubCommand.__init__(self, logger, cmdargs)
  File "/cvmfs/cms.cern.ch/crab3/slc6_amd64_gcc493/cms/crabclient/3.3.1805.patch1/lib/python2.7/site-packages/CRABClient/Commands/SubCommand.py", line 262, in __init__
    self.validateOptions()
  File "/cvmfs/cms.cern.ch/crab3/slc6_amd64_gcc493/cms/crabclient/3.3.1805.patch1/lib/python2.7/site-packages/CRABClient/Commands/status.py", line 1019, in validateOptions
    SubCommand.validateOptions(self)
  File "/cvmfs/cms.cern.ch/crab3/slc6_amd64_gcc493/cms/crabclient/3.3.1805.patch1/lib/python2.7/site-packages/CRABClient/Commands/SubCommand.py", line 575, in validateOptions
    raise ConfigurationException(msg)
ConfigurationException: [91mError[0m: crab_plots_PileupAnalyzer_DY1 is not a valid CRAB project directory.
DEBUG 2018-08-18 18:02:54,329: 	 Executing command: 'status'
DEBUG 2018-08-18 18:02:54,329: 	 Found CRAB cache file /afs/cern.ch/user/p/psiddire/.crab3
ERROR 2018-08-18 18:02:54,330: 	 Error: crab_plots_PileupAnalyzer_STtWt is not a valid CRAB project directory.
ERROR 2018-08-18 18:02:54,330: 	 Caught exception
Traceback (most recent call last):
  File "/cvmfs/cms.cern.ch/crab3/slc6_amd64_gcc493/cms/crabclient/3.3.1805.patch1/bin/crab", line 160, in <module>
    client()
  File "/cvmfs/cms.cern.ch/crab3/slc6_amd64_gcc493/cms/crabclient/3.3.1805.patch1/bin/crab", line 146, in __call__
    self.cmd = sub_cmd(self.logger, args[1:])
  File "/cvmfs/cms.cern.ch/crab3/slc6_amd64_gcc493/cms/crabclient/3.3.1805.patch1/lib/python2.7/site-packages/CRABClient/Commands/status.py", line 39, in __init__
    SubCommand.__init__(self, logger, cmdargs)
  File "/cvmfs/cms.cern.ch/crab3/slc6_amd64_gcc493/cms/crabclient/3.3.1805.patch1/lib/python2.7/site-packages/CRABClient/Commands/SubCommand.py", line 262, in __init__
    self.validateOptions()
  File "/cvmfs/cms.cern.ch/crab3/slc6_amd64_gcc493/cms/crabclient/3.3.1805.patch1/lib/python2.7/site-packages/CRABClient/Commands/status.py", line 1019, in validateOptions
    SubCommand.validateOptions(self)
  File "/cvmfs/cms.cern.ch/crab3/slc6_amd64_gcc493/cms/crabclient/3.3.1805.patch1/lib/python2.7/site-packages/CRABClient/Commands/SubCommand.py", line 575, in validateOptions
    raise ConfigurationException(msg)
ConfigurationException: [91mError[0m: crab_plots_PileupAnalyzer_STtWt is not a valid CRAB project directory.
DEBUG 2018-08-18 18:02:54,781: 	 Executing command: 'status'
DEBUG 2018-08-18 18:02:54,781: 	 Found CRAB cache file /afs/cern.ch/user/p/psiddire/.crab3
ERROR 2018-08-18 18:02:54,782: 	 Error: crab_plots_PileupAnalyzer_W4 is not a valid CRAB project directory.
ERROR 2018-08-18 18:02:54,782: 	 Caught exception
Traceback (most recent call last):
  File "/cvmfs/cms.cern.ch/crab3/slc6_amd64_gcc493/cms/crabclient/3.3.1805.patch1/bin/crab", line 160, in <module>
    client()
  File "/cvmfs/cms.cern.ch/crab3/slc6_amd64_gcc493/cms/crabclient/3.3.1805.patch1/bin/crab", line 146, in __call__
    self.cmd = sub_cmd(self.logger, args[1:])
  File "/cvmfs/cms.cern.ch/crab3/slc6_amd64_gcc493/cms/crabclient/3.3.1805.patch1/lib/python2.7/site-packages/CRABClient/Commands/status.py", line 39, in __init__
    SubCommand.__init__(self, logger, cmdargs)
  File "/cvmfs/cms.cern.ch/crab3/slc6_amd64_gcc493/cms/crabclient/3.3.1805.patch1/lib/python2.7/site-packages/CRABClient/Commands/SubCommand.py", line 262, in __init__
    self.validateOptions()
  File "/cvmfs/cms.cern.ch/crab3/slc6_amd64_gcc493/cms/crabclient/3.3.1805.patch1/lib/python2.7/site-packages/CRABClient/Commands/status.py", line 1019, in validateOptions
    SubCommand.validateOptions(self)
  File "/cvmfs/cms.cern.ch/crab3/slc6_amd64_gcc493/cms/crabclient/3.3.1805.patch1/lib/python2.7/site-packages/CRABClient/Commands/SubCommand.py", line 575, in validateOptions
    raise ConfigurationException(msg)
ConfigurationException: [91mError[0m: crab_plots_PileupAnalyzer_W4 is not a valid CRAB project directory.
DEBUG 2018-08-18 18:02:55,245: 	 Executing command: 'status'
DEBUG 2018-08-18 18:02:55,245: 	 Found CRAB cache file /afs/cern.ch/user/p/psiddire/.crab3
ERROR 2018-08-18 18:02:55,245: 	 Error: crab_plots_PileupAnalyzer_DY2ext1v1 is not a valid CRAB project directory.
ERROR 2018-08-18 18:02:55,246: 	 Caught exception
Traceback (most recent call last):
  File "/cvmfs/cms.cern.ch/crab3/slc6_amd64_gcc493/cms/crabclient/3.3.1805.patch1/bin/crab", line 160, in <module>
    client()
  File "/cvmfs/cms.cern.ch/crab3/slc6_amd64_gcc493/cms/crabclient/3.3.1805.patch1/bin/crab", line 146, in __call__
    self.cmd = sub_cmd(self.logger, args[1:])
  File "/cvmfs/cms.cern.ch/crab3/slc6_amd64_gcc493/cms/crabclient/3.3.1805.patch1/lib/python2.7/site-packages/CRABClient/Commands/status.py", line 39, in __init__
    SubCommand.__init__(self, logger, cmdargs)
  File "/cvmfs/cms.cern.ch/crab3/slc6_amd64_gcc493/cms/crabclient/3.3.1805.patch1/lib/python2.7/site-packages/CRABClient/Commands/SubCommand.py", line 262, in __init__
    self.validateOptions()
  File "/cvmfs/cms.cern.ch/crab3/slc6_amd64_gcc493/cms/crabclient/3.3.1805.patch1/lib/python2.7/site-packages/CRABClient/Commands/status.py", line 1019, in validateOptions
    SubCommand.validateOptions(self)
  File "/cvmfs/cms.cern.ch/crab3/slc6_amd64_gcc493/cms/crabclient/3.3.1805.patch1/lib/python2.7/site-packages/CRABClient/Commands/SubCommand.py", line 575, in validateOptions
    raise ConfigurationException(msg)
ConfigurationException: [91mError[0m: crab_plots_PileupAnalyzer_DY2ext1v1 is not a valid CRAB project directory.
DEBUG 2018-08-18 18:02:55,691: 	 Executing command: 'status'
DEBUG 2018-08-18 18:02:55,691: 	 Found CRAB cache file /afs/cern.ch/user/p/psiddire/.crab3
ERROR 2018-08-18 18:02:55,691: 	 Error: crab_plots_PileupAnalyzer_STtat is not a valid CRAB project directory.
ERROR 2018-08-18 18:02:55,691: 	 Caught exception
Traceback (most recent call last):
  File "/cvmfs/cms.cern.ch/crab3/slc6_amd64_gcc493/cms/crabclient/3.3.1805.patch1/bin/crab", line 160, in <module>
    client()
  File "/cvmfs/cms.cern.ch/crab3/slc6_amd64_gcc493/cms/crabclient/3.3.1805.patch1/bin/crab", line 146, in __call__
    self.cmd = sub_cmd(self.logger, args[1:])
  File "/cvmfs/cms.cern.ch/crab3/slc6_amd64_gcc493/cms/crabclient/3.3.1805.patch1/lib/python2.7/site-packages/CRABClient/Commands/status.py", line 39, in __init__
    SubCommand.__init__(self, logger, cmdargs)
  File "/cvmfs/cms.cern.ch/crab3/slc6_amd64_gcc493/cms/crabclient/3.3.1805.patch1/lib/python2.7/site-packages/CRABClient/Commands/SubCommand.py", line 262, in __init__
    self.validateOptions()
  File "/cvmfs/cms.cern.ch/crab3/slc6_amd64_gcc493/cms/crabclient/3.3.1805.patch1/lib/python2.7/site-packages/CRABClient/Commands/status.py", line 1019, in validateOptions
    SubCommand.validateOptions(self)
  File "/cvmfs/cms.cern.ch/crab3/slc6_amd64_gcc493/cms/crabclient/3.3.1805.patch1/lib/python2.7/site-packages/CRABClient/Commands/SubCommand.py", line 575, in validateOptions
    raise ConfigurationException(msg)
ConfigurationException: [91mError[0m: crab_plots_PileupAnalyzer_STtat is not a valid CRAB project directory.
DEBUG 2018-08-18 18:02:56,143: 	 Executing command: 'status'
DEBUG 2018-08-18 18:02:56,143: 	 Found CRAB cache file /afs/cern.ch/user/p/psiddire/.crab3
ERROR 2018-08-18 18:02:56,144: 	 Error: crab_plots_PileupAnalyzer_WW is not a valid CRAB project directory.
ERROR 2018-08-18 18:02:56,144: 	 Caught exception
Traceback (most recent call last):
  File "/cvmfs/cms.cern.ch/crab3/slc6_amd64_gcc493/cms/crabclient/3.3.1805.patch1/bin/crab", line 160, in <module>
    client()
  File "/cvmfs/cms.cern.ch/crab3/slc6_amd64_gcc493/cms/crabclient/3.3.1805.patch1/bin/crab", line 146, in __call__
    self.cmd = sub_cmd(self.logger, args[1:])
  File "/cvmfs/cms.cern.ch/crab3/slc6_amd64_gcc493/cms/crabclient/3.3.1805.patch1/lib/python2.7/site-packages/CRABClient/Commands/status.py", line 39, in __init__
    SubCommand.__init__(self, logger, cmdargs)
  File "/cvmfs/cms.cern.ch/crab3/slc6_amd64_gcc493/cms/crabclient/3.3.1805.patch1/lib/python2.7/site-packages/CRABClient/Commands/SubCommand.py", line 262, in __init__
    self.validateOptions()
  File "/cvmfs/cms.cern.ch/crab3/slc6_amd64_gcc493/cms/crabclient/3.3.1805.patch1/lib/python2.7/site-packages/CRABClient/Commands/status.py", line 1019, in validateOptions
    SubCommand.validateOptions(self)
  File "/cvmfs/cms.cern.ch/crab3/slc6_amd64_gcc493/cms/crabclient/3.3.1805.patch1/lib/python2.7/site-packages/CRABClient/Commands/SubCommand.py", line 575, in validateOptions
    raise ConfigurationException(msg)
ConfigurationException: [91mError[0m: crab_plots_PileupAnalyzer_WW is not a valid CRAB project directory.
DEBUG 2018-08-18 18:02:56,612: 	 Executing command: 'status'
DEBUG 2018-08-18 18:02:56,612: 	 Found CRAB cache file /afs/cern.ch/user/p/psiddire/.crab3
ERROR 2018-08-18 18:02:56,612: 	 Error: crab_plots_PileupAnalyzer_DY2v1 is not a valid CRAB project directory.
ERROR 2018-08-18 18:02:56,612: 	 Caught exception
Traceback (most recent call last):
  File "/cvmfs/cms.cern.ch/crab3/slc6_amd64_gcc493/cms/crabclient/3.3.1805.patch1/bin/crab", line 160, in <module>
    client()
  File "/cvmfs/cms.cern.ch/crab3/slc6_amd64_gcc493/cms/crabclient/3.3.1805.patch1/bin/crab", line 146, in __call__
    self.cmd = sub_cmd(self.logger, args[1:])
  File "/cvmfs/cms.cern.ch/crab3/slc6_amd64_gcc493/cms/crabclient/3.3.1805.patch1/lib/python2.7/site-packages/CRABClient/Commands/status.py", line 39, in __init__
    SubCommand.__init__(self, logger, cmdargs)
  File "/cvmfs/cms.cern.ch/crab3/slc6_amd64_gcc493/cms/crabclient/3.3.1805.patch1/lib/python2.7/site-packages/CRABClient/Commands/SubCommand.py", line 262, in __init__
    self.validateOptions()
  File "/cvmfs/cms.cern.ch/crab3/slc6_amd64_gcc493/cms/crabclient/3.3.1805.patch1/lib/python2.7/site-packages/CRABClient/Commands/status.py", line 1019, in validateOptions
    SubCommand.validateOptions(self)
  File "/cvmfs/cms.cern.ch/crab3/slc6_amd64_gcc493/cms/crabclient/3.3.1805.patch1/lib/python2.7/site-packages/CRABClient/Commands/SubCommand.py", line 575, in validateOptions
    raise ConfigurationException(msg)
ConfigurationException: [91mError[0m: crab_plots_PileupAnalyzer_DY2v1 is not a valid CRAB project directory.
DEBUG 2018-08-18 18:02:57,104: 	 Executing command: 'status'
DEBUG 2018-08-18 18:02:57,104: 	 Found CRAB cache file /afs/cern.ch/user/p/psiddire/.crab3
ERROR 2018-08-18 18:02:57,105: 	 Error: crab_plots_PileupAnalyzer_STtt is not a valid CRAB project directory.
ERROR 2018-08-18 18:02:57,105: 	 Caught exception
Traceback (most recent call last):
  File "/cvmfs/cms.cern.ch/crab3/slc6_amd64_gcc493/cms/crabclient/3.3.1805.patch1/bin/crab", line 160, in <module>
    client()
  File "/cvmfs/cms.cern.ch/crab3/slc6_amd64_gcc493/cms/crabclient/3.3.1805.patch1/bin/crab", line 146, in __call__
    self.cmd = sub_cmd(self.logger, args[1:])
  File "/cvmfs/cms.cern.ch/crab3/slc6_amd64_gcc493/cms/crabclient/3.3.1805.patch1/lib/python2.7/site-packages/CRABClient/Commands/status.py", line 39, in __init__
    SubCommand.__init__(self, logger, cmdargs)
  File "/cvmfs/cms.cern.ch/crab3/slc6_amd64_gcc493/cms/crabclient/3.3.1805.patch1/lib/python2.7/site-packages/CRABClient/Commands/SubCommand.py", line 262, in __init__
    self.validateOptions()
  File "/cvmfs/cms.cern.ch/crab3/slc6_amd64_gcc493/cms/crabclient/3.3.1805.patch1/lib/python2.7/site-packages/CRABClient/Commands/status.py", line 1019, in validateOptions
    SubCommand.validateOptions(self)
  File "/cvmfs/cms.cern.ch/crab3/slc6_amd64_gcc493/cms/crabclient/3.3.1805.patch1/lib/python2.7/site-packages/CRABClient/Commands/SubCommand.py", line 575, in validateOptions
    raise ConfigurationException(msg)
ConfigurationException: [91mError[0m: crab_plots_PileupAnalyzer_STtt is not a valid CRAB project directory.
DEBUG 2018-08-18 18:02:57,589: 	 Executing command: 'status'
DEBUG 2018-08-18 18:02:57,589: 	 Found CRAB cache file /afs/cern.ch/user/p/psiddire/.crab3
ERROR 2018-08-18 18:02:57,589: 	 Error: crab_plots_PileupAnalyzer_WZ is not a valid CRAB project directory.
ERROR 2018-08-18 18:02:57,590: 	 Caught exception
Traceback (most recent call last):
  File "/cvmfs/cms.cern.ch/crab3/slc6_amd64_gcc493/cms/crabclient/3.3.1805.patch1/bin/crab", line 160, in <module>
    client()
  File "/cvmfs/cms.cern.ch/crab3/slc6_amd64_gcc493/cms/crabclient/3.3.1805.patch1/bin/crab", line 146, in __call__
    self.cmd = sub_cmd(self.logger, args[1:])
  File "/cvmfs/cms.cern.ch/crab3/slc6_amd64_gcc493/cms/crabclient/3.3.1805.patch1/lib/python2.7/site-packages/CRABClient/Commands/status.py", line 39, in __init__
    SubCommand.__init__(self, logger, cmdargs)
  File "/cvmfs/cms.cern.ch/crab3/slc6_amd64_gcc493/cms/crabclient/3.3.1805.patch1/lib/python2.7/site-packages/CRABClient/Commands/SubCommand.py", line 262, in __init__
    self.validateOptions()
  File "/cvmfs/cms.cern.ch/crab3/slc6_amd64_gcc493/cms/crabclient/3.3.1805.patch1/lib/python2.7/site-packages/CRABClient/Commands/status.py", line 1019, in validateOptions
    SubCommand.validateOptions(self)
  File "/cvmfs/cms.cern.ch/crab3/slc6_amd64_gcc493/cms/crabclient/3.3.1805.patch1/lib/python2.7/site-packages/CRABClient/Commands/SubCommand.py", line 575, in validateOptions
    raise ConfigurationException(msg)
ConfigurationException: [91mError[0m: crab_plots_PileupAnalyzer_WZ is not a valid CRAB project directory.
DEBUG 2018-08-18 18:02:58,001: 	 Executing command: 'status'
DEBUG 2018-08-18 18:02:58,002: 	 Found CRAB cache file /afs/cern.ch/user/p/psiddire/.crab3
ERROR 2018-08-18 18:02:58,002: 	 Error: crab_plots_PileupAnalyzer_DY3ext1v1 is not a valid CRAB project directory.
ERROR 2018-08-18 18:02:58,002: 	 Caught exception
Traceback (most recent call last):
  File "/cvmfs/cms.cern.ch/crab3/slc6_amd64_gcc493/cms/crabclient/3.3.1805.patch1/bin/crab", line 160, in <module>
    client()
  File "/cvmfs/cms.cern.ch/crab3/slc6_amd64_gcc493/cms/crabclient/3.3.1805.patch1/bin/crab", line 146, in __call__
    self.cmd = sub_cmd(self.logger, args[1:])
  File "/cvmfs/cms.cern.ch/crab3/slc6_amd64_gcc493/cms/crabclient/3.3.1805.patch1/lib/python2.7/site-packages/CRABClient/Commands/status.py", line 39, in __init__
    SubCommand.__init__(self, logger, cmdargs)
  File "/cvmfs/cms.cern.ch/crab3/slc6_amd64_gcc493/cms/crabclient/3.3.1805.patch1/lib/python2.7/site-packages/CRABClient/Commands/SubCommand.py", line 262, in __init__
    self.validateOptions()
  File "/cvmfs/cms.cern.ch/crab3/slc6_amd64_gcc493/cms/crabclient/3.3.1805.patch1/lib/python2.7/site-packages/CRABClient/Commands/status.py", line 1019, in validateOptions
    SubCommand.validateOptions(self)
  File "/cvmfs/cms.cern.ch/crab3/slc6_amd64_gcc493/cms/crabclient/3.3.1805.patch1/lib/python2.7/site-packages/CRABClient/Commands/SubCommand.py", line 575, in validateOptions
    raise ConfigurationException(msg)
ConfigurationException: [91mError[0m: crab_plots_PileupAnalyzer_DY3ext1v1 is not a valid CRAB project directory.
DEBUG 2018-08-18 18:02:58,402: 	 Executing command: 'status'
DEBUG 2018-08-18 18:02:58,402: 	 Found CRAB cache file /afs/cern.ch/user/p/psiddire/.crab3
ERROR 2018-08-18 18:02:58,402: 	 Error: crab_plots_PileupAnalyzer_TT2h is not a valid CRAB project directory.
ERROR 2018-08-18 18:02:58,402: 	 Caught exception
Traceback (most recent call last):
  File "/cvmfs/cms.cern.ch/crab3/slc6_amd64_gcc493/cms/crabclient/3.3.1805.patch1/bin/crab", line 160, in <module>
    client()
  File "/cvmfs/cms.cern.ch/crab3/slc6_amd64_gcc493/cms/crabclient/3.3.1805.patch1/bin/crab", line 146, in __call__
    self.cmd = sub_cmd(self.logger, args[1:])
  File "/cvmfs/cms.cern.ch/crab3/slc6_amd64_gcc493/cms/crabclient/3.3.1805.patch1/lib/python2.7/site-packages/CRABClient/Commands/status.py", line 39, in __init__
    SubCommand.__init__(self, logger, cmdargs)
  File "/cvmfs/cms.cern.ch/crab3/slc6_amd64_gcc493/cms/crabclient/3.3.1805.patch1/lib/python2.7/site-packages/CRABClient/Commands/SubCommand.py", line 262, in __init__
    self.validateOptions()
  File "/cvmfs/cms.cern.ch/crab3/slc6_amd64_gcc493/cms/crabclient/3.3.1805.patch1/lib/python2.7/site-packages/CRABClient/Commands/status.py", line 1019, in validateOptions
    SubCommand.validateOptions(self)
  File "/cvmfs/cms.cern.ch/crab3/slc6_amd64_gcc493/cms/crabclient/3.3.1805.patch1/lib/python2.7/site-packages/CRABClient/Commands/SubCommand.py", line 575, in validateOptions
    raise ConfigurationException(msg)
ConfigurationException: [91mError[0m: crab_plots_PileupAnalyzer_TT2h is not a valid CRAB project directory.
DEBUG 2018-08-18 18:02:58,843: 	 Executing command: 'status'
DEBUG 2018-08-18 18:02:58,843: 	 Found CRAB cache file /afs/cern.ch/user/p/psiddire/.crab3
ERROR 2018-08-18 18:02:58,844: 	 Error: crab_plots_PileupAnalyzer_Wext1v2 is not a valid CRAB project directory.
ERROR 2018-08-18 18:02:58,844: 	 Caught exception
Traceback (most recent call last):
  File "/cvmfs/cms.cern.ch/crab3/slc6_amd64_gcc493/cms/crabclient/3.3.1805.patch1/bin/crab", line 160, in <module>
    client()
  File "/cvmfs/cms.cern.ch/crab3/slc6_amd64_gcc493/cms/crabclient/3.3.1805.patch1/bin/crab", line 146, in __call__
    self.cmd = sub_cmd(self.logger, args[1:])
  File "/cvmfs/cms.cern.ch/crab3/slc6_amd64_gcc493/cms/crabclient/3.3.1805.patch1/lib/python2.7/site-packages/CRABClient/Commands/status.py", line 39, in __init__
    SubCommand.__init__(self, logger, cmdargs)
  File "/cvmfs/cms.cern.ch/crab3/slc6_amd64_gcc493/cms/crabclient/3.3.1805.patch1/lib/python2.7/site-packages/CRABClient/Commands/SubCommand.py", line 262, in __init__
    self.validateOptions()
  File "/cvmfs/cms.cern.ch/crab3/slc6_amd64_gcc493/cms/crabclient/3.3.1805.patch1/lib/python2.7/site-packages/CRABClient/Commands/status.py", line 1019, in validateOptions
    SubCommand.validateOptions(self)
  File "/cvmfs/cms.cern.ch/crab3/slc6_amd64_gcc493/cms/crabclient/3.3.1805.patch1/lib/python2.7/site-packages/CRABClient/Commands/SubCommand.py", line 575, in validateOptions
    raise ConfigurationException(msg)
ConfigurationException: [91mError[0m: crab_plots_PileupAnalyzer_Wext1v2 is not a valid CRAB project directory.
DEBUG 2018-08-18 18:02:59,260: 	 Executing command: 'status'
DEBUG 2018-08-18 18:02:59,260: 	 Found CRAB cache file /afs/cern.ch/user/p/psiddire/.crab3
ERROR 2018-08-18 18:02:59,261: 	 Error: crab_plots_PileupAnalyzer_DY3v1 is not a valid CRAB project directory.
ERROR 2018-08-18 18:02:59,261: 	 Caught exception
Traceback (most recent call last):
  File "/cvmfs/cms.cern.ch/crab3/slc6_amd64_gcc493/cms/crabclient/3.3.1805.patch1/bin/crab", line 160, in <module>
    client()
  File "/cvmfs/cms.cern.ch/crab3/slc6_amd64_gcc493/cms/crabclient/3.3.1805.patch1/bin/crab", line 146, in __call__
    self.cmd = sub_cmd(self.logger, args[1:])
  File "/cvmfs/cms.cern.ch/crab3/slc6_amd64_gcc493/cms/crabclient/3.3.1805.patch1/lib/python2.7/site-packages/CRABClient/Commands/status.py", line 39, in __init__
    SubCommand.__init__(self, logger, cmdargs)
  File "/cvmfs/cms.cern.ch/crab3/slc6_amd64_gcc493/cms/crabclient/3.3.1805.patch1/lib/python2.7/site-packages/CRABClient/Commands/SubCommand.py", line 262, in __init__
    self.validateOptions()
  File "/cvmfs/cms.cern.ch/crab3/slc6_amd64_gcc493/cms/crabclient/3.3.1805.patch1/lib/python2.7/site-packages/CRABClient/Commands/status.py", line 1019, in validateOptions
    SubCommand.validateOptions(self)
  File "/cvmfs/cms.cern.ch/crab3/slc6_amd64_gcc493/cms/crabclient/3.3.1805.patch1/lib/python2.7/site-packages/CRABClient/Commands/SubCommand.py", line 575, in validateOptions
    raise ConfigurationException(msg)
ConfigurationException: [91mError[0m: crab_plots_PileupAnalyzer_DY3v1 is not a valid CRAB project directory.
DEBUG 2018-08-18 18:02:59,678: 	 Executing command: 'status'
DEBUG 2018-08-18 18:02:59,678: 	 Found CRAB cache file /afs/cern.ch/user/p/psiddire/.crab3
ERROR 2018-08-18 18:02:59,678: 	 Error: crab_plots_PileupAnalyzer_TT2l is not a valid CRAB project directory.
ERROR 2018-08-18 18:02:59,679: 	 Caught exception
Traceback (most recent call last):
  File "/cvmfs/cms.cern.ch/crab3/slc6_amd64_gcc493/cms/crabclient/3.3.1805.patch1/bin/crab", line 160, in <module>
    client()
  File "/cvmfs/cms.cern.ch/crab3/slc6_amd64_gcc493/cms/crabclient/3.3.1805.patch1/bin/crab", line 146, in __call__
    self.cmd = sub_cmd(self.logger, args[1:])
  File "/cvmfs/cms.cern.ch/crab3/slc6_amd64_gcc493/cms/crabclient/3.3.1805.patch1/lib/python2.7/site-packages/CRABClient/Commands/status.py", line 39, in __init__
    SubCommand.__init__(self, logger, cmdargs)
  File "/cvmfs/cms.cern.ch/crab3/slc6_amd64_gcc493/cms/crabclient/3.3.1805.patch1/lib/python2.7/site-packages/CRABClient/Commands/SubCommand.py", line 262, in __init__
    self.validateOptions()
  File "/cvmfs/cms.cern.ch/crab3/slc6_amd64_gcc493/cms/crabclient/3.3.1805.patch1/lib/python2.7/site-packages/CRABClient/Commands/status.py", line 1019, in validateOptions
    SubCommand.validateOptions(self)
  File "/cvmfs/cms.cern.ch/crab3/slc6_amd64_gcc493/cms/crabclient/3.3.1805.patch1/lib/python2.7/site-packages/CRABClient/Commands/SubCommand.py", line 575, in validateOptions
    raise ConfigurationException(msg)
ConfigurationException: [91mError[0m: crab_plots_PileupAnalyzer_TT2l is not a valid CRAB project directory.
DEBUG 2018-08-18 18:03:00,098: 	 Executing command: 'status'
DEBUG 2018-08-18 18:03:00,098: 	 Found CRAB cache file /afs/cern.ch/user/p/psiddire/.crab3
ERROR 2018-08-18 18:03:00,099: 	 Error: crab_plots_PileupAnalyzer_Wm is not a valid CRAB project directory.
ERROR 2018-08-18 18:03:00,099: 	 Caught exception
Traceback (most recent call last):
  File "/cvmfs/cms.cern.ch/crab3/slc6_amd64_gcc493/cms/crabclient/3.3.1805.patch1/bin/crab", line 160, in <module>
    client()
  File "/cvmfs/cms.cern.ch/crab3/slc6_amd64_gcc493/cms/crabclient/3.3.1805.patch1/bin/crab", line 146, in __call__
    self.cmd = sub_cmd(self.logger, args[1:])
  File "/cvmfs/cms.cern.ch/crab3/slc6_amd64_gcc493/cms/crabclient/3.3.1805.patch1/lib/python2.7/site-packages/CRABClient/Commands/status.py", line 39, in __init__
    SubCommand.__init__(self, logger, cmdargs)
  File "/cvmfs/cms.cern.ch/crab3/slc6_amd64_gcc493/cms/crabclient/3.3.1805.patch1/lib/python2.7/site-packages/CRABClient/Commands/SubCommand.py", line 262, in __init__
    self.validateOptions()
  File "/cvmfs/cms.cern.ch/crab3/slc6_amd64_gcc493/cms/crabclient/3.3.1805.patch1/lib/python2.7/site-packages/CRABClient/Commands/status.py", line 1019, in validateOptions
    SubCommand.validateOptions(self)
  File "/cvmfs/cms.cern.ch/crab3/slc6_amd64_gcc493/cms/crabclient/3.3.1805.patch1/lib/python2.7/site-packages/CRABClient/Commands/SubCommand.py", line 575, in validateOptions
    raise ConfigurationException(msg)
ConfigurationException: [91mError[0m: crab_plots_PileupAnalyzer_Wm is not a valid CRAB project directory.
DEBUG 2018-08-18 18:03:00,492: 	 Executing command: 'status'
DEBUG 2018-08-18 18:03:00,492: 	 Found CRAB cache file /afs/cern.ch/user/p/psiddire/.crab3
ERROR 2018-08-18 18:03:00,493: 	 Error: crab_plots_PileupAnalyzer_DY4 is not a valid CRAB project directory.
ERROR 2018-08-18 18:03:00,493: 	 Caught exception
Traceback (most recent call last):
  File "/cvmfs/cms.cern.ch/crab3/slc6_amd64_gcc493/cms/crabclient/3.3.1805.patch1/bin/crab", line 160, in <module>
    client()
  File "/cvmfs/cms.cern.ch/crab3/slc6_amd64_gcc493/cms/crabclient/3.3.1805.patch1/bin/crab", line 146, in __call__
    self.cmd = sub_cmd(self.logger, args[1:])
  File "/cvmfs/cms.cern.ch/crab3/slc6_amd64_gcc493/cms/crabclient/3.3.1805.patch1/lib/python2.7/site-packages/CRABClient/Commands/status.py", line 39, in __init__
    SubCommand.__init__(self, logger, cmdargs)
  File "/cvmfs/cms.cern.ch/crab3/slc6_amd64_gcc493/cms/crabclient/3.3.1805.patch1/lib/python2.7/site-packages/CRABClient/Commands/SubCommand.py", line 262, in __init__
    self.validateOptions()
  File "/cvmfs/cms.cern.ch/crab3/slc6_amd64_gcc493/cms/crabclient/3.3.1805.patch1/lib/python2.7/site-packages/CRABClient/Commands/status.py", line 1019, in validateOptions
    SubCommand.validateOptions(self)
  File "/cvmfs/cms.cern.ch/crab3/slc6_amd64_gcc493/cms/crabclient/3.3.1805.patch1/lib/python2.7/site-packages/CRABClient/Commands/SubCommand.py", line 575, in validateOptions
    raise ConfigurationException(msg)
ConfigurationException: [91mError[0m: crab_plots_PileupAnalyzer_DY4 is not a valid CRAB project directory.
DEBUG 2018-08-18 18:03:00,942: 	 Executing command: 'status'
DEBUG 2018-08-18 18:03:00,943: 	 Found CRAB cache file /afs/cern.ch/user/p/psiddire/.crab3
ERROR 2018-08-18 18:03:00,944: 	 Error: crab_plots_PileupAnalyzer_TT2s is not a valid CRAB project directory.
ERROR 2018-08-18 18:03:00,944: 	 Caught exception
Traceback (most recent call last):
  File "/cvmfs/cms.cern.ch/crab3/slc6_amd64_gcc493/cms/crabclient/3.3.1805.patch1/bin/crab", line 160, in <module>
    client()
  File "/cvmfs/cms.cern.ch/crab3/slc6_amd64_gcc493/cms/crabclient/3.3.1805.patch1/bin/crab", line 146, in __call__
    self.cmd = sub_cmd(self.logger, args[1:])
  File "/cvmfs/cms.cern.ch/crab3/slc6_amd64_gcc493/cms/crabclient/3.3.1805.patch1/lib/python2.7/site-packages/CRABClient/Commands/status.py", line 39, in __init__
    SubCommand.__init__(self, logger, cmdargs)
  File "/cvmfs/cms.cern.ch/crab3/slc6_amd64_gcc493/cms/crabclient/3.3.1805.patch1/lib/python2.7/site-packages/CRABClient/Commands/SubCommand.py", line 262, in __init__
    self.validateOptions()
  File "/cvmfs/cms.cern.ch/crab3/slc6_amd64_gcc493/cms/crabclient/3.3.1805.patch1/lib/python2.7/site-packages/CRABClient/Commands/status.py", line 1019, in validateOptions
    SubCommand.validateOptions(self)
  File "/cvmfs/cms.cern.ch/crab3/slc6_amd64_gcc493/cms/crabclient/3.3.1805.patch1/lib/python2.7/site-packages/CRABClient/Commands/SubCommand.py", line 575, in validateOptions
    raise ConfigurationException(msg)
ConfigurationException: [91mError[0m: crab_plots_PileupAnalyzer_TT2s is not a valid CRAB project directory.
DEBUG 2018-08-18 18:03:01,542: 	 Executing command: 'status'
DEBUG 2018-08-18 18:03:01,542: 	 Found CRAB cache file /afs/cern.ch/user/p/psiddire/.crab3
ERROR 2018-08-18 18:03:01,542: 	 Error: crab_plots_PileupAnalyzer_Wp is not a valid CRAB project directory.
ERROR 2018-08-18 18:03:01,542: 	 Caught exception
Traceback (most recent call last):
  File "/cvmfs/cms.cern.ch/crab3/slc6_amd64_gcc493/cms/crabclient/3.3.1805.patch1/bin/crab", line 160, in <module>
    client()
  File "/cvmfs/cms.cern.ch/crab3/slc6_amd64_gcc493/cms/crabclient/3.3.1805.patch1/bin/crab", line 146, in __call__
    self.cmd = sub_cmd(self.logger, args[1:])
  File "/cvmfs/cms.cern.ch/crab3/slc6_amd64_gcc493/cms/crabclient/3.3.1805.patch1/lib/python2.7/site-packages/CRABClient/Commands/status.py", line 39, in __init__
    SubCommand.__init__(self, logger, cmdargs)
  File "/cvmfs/cms.cern.ch/crab3/slc6_amd64_gcc493/cms/crabclient/3.3.1805.patch1/lib/python2.7/site-packages/CRABClient/Commands/SubCommand.py", line 262, in __init__
    self.validateOptions()
  File "/cvmfs/cms.cern.ch/crab3/slc6_amd64_gcc493/cms/crabclient/3.3.1805.patch1/lib/python2.7/site-packages/CRABClient/Commands/status.py", line 1019, in validateOptions
    SubCommand.validateOptions(self)
  File "/cvmfs/cms.cern.ch/crab3/slc6_amd64_gcc493/cms/crabclient/3.3.1805.patch1/lib/python2.7/site-packages/CRABClient/Commands/SubCommand.py", line 575, in validateOptions
    raise ConfigurationException(msg)
ConfigurationException: [91mError[0m: crab_plots_PileupAnalyzer_Wp is not a valid CRAB project directory.
DEBUG 2018-08-18 18:03:01,923: 	 Executing command: 'status'
DEBUG 2018-08-18 18:03:01,923: 	 Found CRAB cache file /afs/cern.ch/user/p/psiddire/.crab3
ERROR 2018-08-18 18:03:01,923: 	 Error: crab_plots_PileupAnalyzer_DYext1v1 is not a valid CRAB project directory.
ERROR 2018-08-18 18:03:01,923: 	 Caught exception
Traceback (most recent call last):
  File "/cvmfs/cms.cern.ch/crab3/slc6_amd64_gcc493/cms/crabclient/3.3.1805.patch1/bin/crab", line 160, in <module>
    client()
  File "/cvmfs/cms.cern.ch/crab3/slc6_amd64_gcc493/cms/crabclient/3.3.1805.patch1/bin/crab", line 146, in __call__
    self.cmd = sub_cmd(self.logger, args[1:])
  File "/cvmfs/cms.cern.ch/crab3/slc6_amd64_gcc493/cms/crabclient/3.3.1805.patch1/lib/python2.7/site-packages/CRABClient/Commands/status.py", line 39, in __init__
    SubCommand.__init__(self, logger, cmdargs)
  File "/cvmfs/cms.cern.ch/crab3/slc6_amd64_gcc493/cms/crabclient/3.3.1805.patch1/lib/python2.7/site-packages/CRABClient/Commands/SubCommand.py", line 262, in __init__
    self.validateOptions()
  File "/cvmfs/cms.cern.ch/crab3/slc6_amd64_gcc493/cms/crabclient/3.3.1805.patch1/lib/python2.7/site-packages/CRABClient/Commands/status.py", line 1019, in validateOptions
    SubCommand.validateOptions(self)
  File "/cvmfs/cms.cern.ch/crab3/slc6_amd64_gcc493/cms/crabclient/3.3.1805.patch1/lib/python2.7/site-packages/CRABClient/Commands/SubCommand.py", line 575, in validateOptions
    raise ConfigurationException(msg)
ConfigurationException: [91mError[0m: crab_plots_PileupAnalyzer_DYext1v1 is not a valid CRAB project directory.
DEBUG 2018-08-18 18:03:02,337: 	 Executing command: 'status'
DEBUG 2018-08-18 18:03:02,337: 	 Found CRAB cache file /afs/cern.ch/user/p/psiddire/.crab3
ERROR 2018-08-18 18:03:02,337: 	 Error: crab_plots_PileupAnalyzer_VBF is not a valid CRAB project directory.
ERROR 2018-08-18 18:03:02,338: 	 Caught exception
Traceback (most recent call last):
  File "/cvmfs/cms.cern.ch/crab3/slc6_amd64_gcc493/cms/crabclient/3.3.1805.patch1/bin/crab", line 160, in <module>
    client()
  File "/cvmfs/cms.cern.ch/crab3/slc6_amd64_gcc493/cms/crabclient/3.3.1805.patch1/bin/crab", line 146, in __call__
    self.cmd = sub_cmd(self.logger, args[1:])
  File "/cvmfs/cms.cern.ch/crab3/slc6_amd64_gcc493/cms/crabclient/3.3.1805.patch1/lib/python2.7/site-packages/CRABClient/Commands/status.py", line 39, in __init__
    SubCommand.__init__(self, logger, cmdargs)
  File "/cvmfs/cms.cern.ch/crab3/slc6_amd64_gcc493/cms/crabclient/3.3.1805.patch1/lib/python2.7/site-packages/CRABClient/Commands/SubCommand.py", line 262, in __init__
    self.validateOptions()
  File "/cvmfs/cms.cern.ch/crab3/slc6_amd64_gcc493/cms/crabclient/3.3.1805.patch1/lib/python2.7/site-packages/CRABClient/Commands/status.py", line 1019, in validateOptions
    SubCommand.validateOptions(self)
  File "/cvmfs/cms.cern.ch/crab3/slc6_amd64_gcc493/cms/crabclient/3.3.1805.patch1/lib/python2.7/site-packages/CRABClient/Commands/SubCommand.py", line 575, in validateOptions
    raise ConfigurationException(msg)
ConfigurationException: [91mError[0m: crab_plots_PileupAnalyzer_VBF is not a valid CRAB project directory.
DEBUG 2018-08-18 18:03:02,817: 	 Executing command: 'status'
DEBUG 2018-08-18 18:03:02,817: 	 Found CRAB cache file /afs/cern.ch/user/p/psiddire/.crab3
ERROR 2018-08-18 18:03:02,817: 	 Error: crab_plots_PileupAnalyzer_Wv2 is not a valid CRAB project directory.
ERROR 2018-08-18 18:03:02,817: 	 Caught exception
Traceback (most recent call last):
  File "/cvmfs/cms.cern.ch/crab3/slc6_amd64_gcc493/cms/crabclient/3.3.1805.patch1/bin/crab", line 160, in <module>
    client()
  File "/cvmfs/cms.cern.ch/crab3/slc6_amd64_gcc493/cms/crabclient/3.3.1805.patch1/bin/crab", line 146, in __call__
    self.cmd = sub_cmd(self.logger, args[1:])
  File "/cvmfs/cms.cern.ch/crab3/slc6_amd64_gcc493/cms/crabclient/3.3.1805.patch1/lib/python2.7/site-packages/CRABClient/Commands/status.py", line 39, in __init__
    SubCommand.__init__(self, logger, cmdargs)
  File "/cvmfs/cms.cern.ch/crab3/slc6_amd64_gcc493/cms/crabclient/3.3.1805.patch1/lib/python2.7/site-packages/CRABClient/Commands/SubCommand.py", line 262, in __init__
    self.validateOptions()
  File "/cvmfs/cms.cern.ch/crab3/slc6_amd64_gcc493/cms/crabclient/3.3.1805.patch1/lib/python2.7/site-packages/CRABClient/Commands/status.py", line 1019, in validateOptions
    SubCommand.validateOptions(self)
  File "/cvmfs/cms.cern.ch/crab3/slc6_amd64_gcc493/cms/crabclient/3.3.1805.patch1/lib/python2.7/site-packages/CRABClient/Commands/SubCommand.py", line 575, in validateOptions
    raise ConfigurationException(msg)
ConfigurationException: [91mError[0m: crab_plots_PileupAnalyzer_Wv2 is not a valid CRAB project directory.
DEBUG 2018-08-18 18:03:03,265: 	 Executing command: 'status'
DEBUG 2018-08-18 18:03:03,265: 	 Found CRAB cache file /afs/cern.ch/user/p/psiddire/.crab3
ERROR 2018-08-18 18:03:03,265: 	 Error: crab_plots_PileupAnalyzer_DYv1 is not a valid CRAB project directory.
ERROR 2018-08-18 18:03:03,265: 	 Caught exception
Traceback (most recent call last):
  File "/cvmfs/cms.cern.ch/crab3/slc6_amd64_gcc493/cms/crabclient/3.3.1805.patch1/bin/crab", line 160, in <module>
    client()
  File "/cvmfs/cms.cern.ch/crab3/slc6_amd64_gcc493/cms/crabclient/3.3.1805.patch1/bin/crab", line 146, in __call__
    self.cmd = sub_cmd(self.logger, args[1:])
  File "/cvmfs/cms.cern.ch/crab3/slc6_amd64_gcc493/cms/crabclient/3.3.1805.patch1/lib/python2.7/site-packages/CRABClient/Commands/status.py", line 39, in __init__
    SubCommand.__init__(self, logger, cmdargs)
  File "/cvmfs/cms.cern.ch/crab3/slc6_amd64_gcc493/cms/crabclient/3.3.1805.patch1/lib/python2.7/site-packages/CRABClient/Commands/SubCommand.py", line 262, in __init__
    self.validateOptions()
  File "/cvmfs/cms.cern.ch/crab3/slc6_amd64_gcc493/cms/crabclient/3.3.1805.patch1/lib/python2.7/site-packages/CRABClient/Commands/status.py", line 1019, in validateOptions
    SubCommand.validateOptions(self)
  File "/cvmfs/cms.cern.ch/crab3/slc6_amd64_gcc493/cms/crabclient/3.3.1805.patch1/lib/python2.7/site-packages/CRABClient/Commands/SubCommand.py", line 575, in validateOptions
    raise ConfigurationException(msg)
ConfigurationException: [91mError[0m: crab_plots_PileupAnalyzer_DYv1 is not a valid CRAB project directory.
DEBUG 2018-08-18 18:03:03,691: 	 Executing command: 'status'
DEBUG 2018-08-18 18:03:03,691: 	 Found CRAB cache file /afs/cern.ch/user/p/psiddire/.crab3
ERROR 2018-08-18 18:03:03,691: 	 Error: crab_plots_PileupAnalyzer_VBFH is not a valid CRAB project directory.
ERROR 2018-08-18 18:03:03,692: 	 Caught exception
Traceback (most recent call last):
  File "/cvmfs/cms.cern.ch/crab3/slc6_amd64_gcc493/cms/crabclient/3.3.1805.patch1/bin/crab", line 160, in <module>
    client()
  File "/cvmfs/cms.cern.ch/crab3/slc6_amd64_gcc493/cms/crabclient/3.3.1805.patch1/bin/crab", line 146, in __call__
    self.cmd = sub_cmd(self.logger, args[1:])
  File "/cvmfs/cms.cern.ch/crab3/slc6_amd64_gcc493/cms/crabclient/3.3.1805.patch1/lib/python2.7/site-packages/CRABClient/Commands/status.py", line 39, in __init__
    SubCommand.__init__(self, logger, cmdargs)
  File "/cvmfs/cms.cern.ch/crab3/slc6_amd64_gcc493/cms/crabclient/3.3.1805.patch1/lib/python2.7/site-packages/CRABClient/Commands/SubCommand.py", line 262, in __init__
    self.validateOptions()
  File "/cvmfs/cms.cern.ch/crab3/slc6_amd64_gcc493/cms/crabclient/3.3.1805.patch1/lib/python2.7/site-packages/CRABClient/Commands/status.py", line 1019, in validateOptions
    SubCommand.validateOptions(self)
  File "/cvmfs/cms.cern.ch/crab3/slc6_amd64_gcc493/cms/crabclient/3.3.1805.patch1/lib/python2.7/site-packages/CRABClient/Commands/SubCommand.py", line 575, in validateOptions
    raise ConfigurationException(msg)
ConfigurationException: [91mError[0m: crab_plots_PileupAnalyzer_VBFH is not a valid CRAB project directory.
DEBUG 2018-08-18 18:03:04,095: 	 Executing command: 'status'
DEBUG 2018-08-18 18:03:04,095: 	 Found CRAB cache file /afs/cern.ch/user/p/psiddire/.crab3
ERROR 2018-08-18 18:03:04,095: 	 Error: crab_plots_PileupAnalyzer_ZH is not a valid CRAB project directory.
ERROR 2018-08-18 18:03:04,096: 	 Caught exception
Traceback (most recent call last):
  File "/cvmfs/cms.cern.ch/crab3/slc6_amd64_gcc493/cms/crabclient/3.3.1805.patch1/bin/crab", line 160, in <module>
    client()
  File "/cvmfs/cms.cern.ch/crab3/slc6_amd64_gcc493/cms/crabclient/3.3.1805.patch1/bin/crab", line 146, in __call__
    self.cmd = sub_cmd(self.logger, args[1:])
  File "/cvmfs/cms.cern.ch/crab3/slc6_amd64_gcc493/cms/crabclient/3.3.1805.patch1/lib/python2.7/site-packages/CRABClient/Commands/status.py", line 39, in __init__
    SubCommand.__init__(self, logger, cmdargs)
  File "/cvmfs/cms.cern.ch/crab3/slc6_amd64_gcc493/cms/crabclient/3.3.1805.patch1/lib/python2.7/site-packages/CRABClient/Commands/SubCommand.py", line 262, in __init__
    self.validateOptions()
  File "/cvmfs/cms.cern.ch/crab3/slc6_amd64_gcc493/cms/crabclient/3.3.1805.patch1/lib/python2.7/site-packages/CRABClient/Commands/status.py", line 1019, in validateOptions
    SubCommand.validateOptions(self)
  File "/cvmfs/cms.cern.ch/crab3/slc6_amd64_gcc493/cms/crabclient/3.3.1805.patch1/lib/python2.7/site-packages/CRABClient/Commands/SubCommand.py", line 575, in validateOptions
    raise ConfigurationException(msg)
ConfigurationException: [91mError[0m: crab_plots_PileupAnalyzer_ZH is not a valid CRAB project directory.
DEBUG 2018-08-18 18:03:04,522: 	 Executing command: 'status'
DEBUG 2018-08-18 18:03:04,522: 	 Found CRAB cache file /afs/cern.ch/user/p/psiddire/.crab3
ERROR 2018-08-18 18:03:04,523: 	 Error: crab_plots_PileupAnalyzer_GG is not a valid CRAB project directory.
ERROR 2018-08-18 18:03:04,523: 	 Caught exception
Traceback (most recent call last):
  File "/cvmfs/cms.cern.ch/crab3/slc6_amd64_gcc493/cms/crabclient/3.3.1805.patch1/bin/crab", line 160, in <module>
    client()
  File "/cvmfs/cms.cern.ch/crab3/slc6_amd64_gcc493/cms/crabclient/3.3.1805.patch1/bin/crab", line 146, in __call__
    self.cmd = sub_cmd(self.logger, args[1:])
  File "/cvmfs/cms.cern.ch/crab3/slc6_amd64_gcc493/cms/crabclient/3.3.1805.patch1/lib/python2.7/site-packages/CRABClient/Commands/status.py", line 39, in __init__
    SubCommand.__init__(self, logger, cmdargs)
  File "/cvmfs/cms.cern.ch/crab3/slc6_amd64_gcc493/cms/crabclient/3.3.1805.patch1/lib/python2.7/site-packages/CRABClient/Commands/SubCommand.py", line 262, in __init__
    self.validateOptions()
  File "/cvmfs/cms.cern.ch/crab3/slc6_amd64_gcc493/cms/crabclient/3.3.1805.patch1/lib/python2.7/site-packages/CRABClient/Commands/status.py", line 1019, in validateOptions
    SubCommand.validateOptions(self)
  File "/cvmfs/cms.cern.ch/crab3/slc6_amd64_gcc493/cms/crabclient/3.3.1805.patch1/lib/python2.7/site-packages/CRABClient/Commands/SubCommand.py", line 575, in validateOptions
    raise ConfigurationException(msg)
ConfigurationException: [91mError[0m: crab_plots_PileupAnalyzer_GG is not a valid CRAB project directory.
DEBUG 2018-08-18 18:03:04,942: 	 Executing command: 'status'
DEBUG 2018-08-18 18:03:04,942: 	 Found CRAB cache file /afs/cern.ch/user/p/psiddire/.crab3
ERROR 2018-08-18 18:03:04,943: 	 Error: crab_plots_PileupAnalyzer_W1 is not a valid CRAB project directory.
ERROR 2018-08-18 18:03:04,943: 	 Caught exception
Traceback (most recent call last):
  File "/cvmfs/cms.cern.ch/crab3/slc6_amd64_gcc493/cms/crabclient/3.3.1805.patch1/bin/crab", line 160, in <module>
    client()
  File "/cvmfs/cms.cern.ch/crab3/slc6_amd64_gcc493/cms/crabclient/3.3.1805.patch1/bin/crab", line 146, in __call__
    self.cmd = sub_cmd(self.logger, args[1:])
  File "/cvmfs/cms.cern.ch/crab3/slc6_amd64_gcc493/cms/crabclient/3.3.1805.patch1/lib/python2.7/site-packages/CRABClient/Commands/status.py", line 39, in __init__
    SubCommand.__init__(self, logger, cmdargs)
  File "/cvmfs/cms.cern.ch/crab3/slc6_amd64_gcc493/cms/crabclient/3.3.1805.patch1/lib/python2.7/site-packages/CRABClient/Commands/SubCommand.py", line 262, in __init__
    self.validateOptions()
  File "/cvmfs/cms.cern.ch/crab3/slc6_amd64_gcc493/cms/crabclient/3.3.1805.patch1/lib/python2.7/site-packages/CRABClient/Commands/status.py", line 1019, in validateOptions
    SubCommand.validateOptions(self)
  File "/cvmfs/cms.cern.ch/crab3/slc6_amd64_gcc493/cms/crabclient/3.3.1805.patch1/lib/python2.7/site-packages/CRABClient/Commands/SubCommand.py", line 575, in validateOptions
    raise ConfigurationException(msg)
ConfigurationException: [91mError[0m: crab_plots_PileupAnalyzer_W1 is not a valid CRAB project directory.
DEBUG 2018-08-18 18:03:05,419: 	 Executing command: 'status'
DEBUG 2018-08-18 18:03:05,419: 	 Found CRAB cache file /afs/cern.ch/user/p/psiddire/.crab3
ERROR 2018-08-18 18:03:05,419: 	 Error: crab_plots_PileupAnalyzer_ZZ is not a valid CRAB project directory.
ERROR 2018-08-18 18:03:05,419: 	 Caught exception
Traceback (most recent call last):
  File "/cvmfs/cms.cern.ch/crab3/slc6_amd64_gcc493/cms/crabclient/3.3.1805.patch1/bin/crab", line 160, in <module>
    client()
  File "/cvmfs/cms.cern.ch/crab3/slc6_amd64_gcc493/cms/crabclient/3.3.1805.patch1/bin/crab", line 146, in __call__
    self.cmd = sub_cmd(self.logger, args[1:])
  File "/cvmfs/cms.cern.ch/crab3/slc6_amd64_gcc493/cms/crabclient/3.3.1805.patch1/lib/python2.7/site-packages/CRABClient/Commands/status.py", line 39, in __init__
    SubCommand.__init__(self, logger, cmdargs)
  File "/cvmfs/cms.cern.ch/crab3/slc6_amd64_gcc493/cms/crabclient/3.3.1805.patch1/lib/python2.7/site-packages/CRABClient/Commands/SubCommand.py", line 262, in __init__
    self.validateOptions()
  File "/cvmfs/cms.cern.ch/crab3/slc6_amd64_gcc493/cms/crabclient/3.3.1805.patch1/lib/python2.7/site-packages/CRABClient/Commands/status.py", line 1019, in validateOptions
    SubCommand.validateOptions(self)
  File "/cvmfs/cms.cern.ch/crab3/slc6_amd64_gcc493/cms/crabclient/3.3.1805.patch1/lib/python2.7/site-packages/CRABClient/Commands/SubCommand.py", line 575, in validateOptions
    raise ConfigurationException(msg)
ConfigurationException: [91mError[0m: crab_plots_PileupAnalyzer_ZZ is not a valid CRAB project directory.
DEBUG 2018-08-18 18:03:05,818: 	 Executing command: 'status'
DEBUG 2018-08-18 18:03:05,818: 	 Found CRAB cache file /afs/cern.ch/user/p/psiddire/.crab3
ERROR 2018-08-18 18:03:05,819: 	 Error: crab_plots_PileupAnalyzer_GGH is not a valid CRAB project directory.
ERROR 2018-08-18 18:03:05,819: 	 Caught exception
Traceback (most recent call last):
  File "/cvmfs/cms.cern.ch/crab3/slc6_amd64_gcc493/cms/crabclient/3.3.1805.patch1/bin/crab", line 160, in <module>
    client()
  File "/cvmfs/cms.cern.ch/crab3/slc6_amd64_gcc493/cms/crabclient/3.3.1805.patch1/bin/crab", line 146, in __call__
    self.cmd = sub_cmd(self.logger, args[1:])
  File "/cvmfs/cms.cern.ch/crab3/slc6_amd64_gcc493/cms/crabclient/3.3.1805.patch1/lib/python2.7/site-packages/CRABClient/Commands/status.py", line 39, in __init__
    SubCommand.__init__(self, logger, cmdargs)
  File "/cvmfs/cms.cern.ch/crab3/slc6_amd64_gcc493/cms/crabclient/3.3.1805.patch1/lib/python2.7/site-packages/CRABClient/Commands/SubCommand.py", line 262, in __init__
    self.validateOptions()
  File "/cvmfs/cms.cern.ch/crab3/slc6_amd64_gcc493/cms/crabclient/3.3.1805.patch1/lib/python2.7/site-packages/CRABClient/Commands/status.py", line 1019, in validateOptions
    SubCommand.validateOptions(self)
  File "/cvmfs/cms.cern.ch/crab3/slc6_amd64_gcc493/cms/crabclient/3.3.1805.patch1/lib/python2.7/site-packages/CRABClient/Commands/SubCommand.py", line 575, in validateOptions
    raise ConfigurationException(msg)
ConfigurationException: [91mError[0m: crab_plots_PileupAnalyzer_GGH is not a valid CRAB project directory.
DEBUG 2018-08-18 18:03:06,248: 	 Executing command: 'status'
DEBUG 2018-08-18 18:03:06,248: 	 Found CRAB cache file /afs/cern.ch/user/p/psiddire/.crab3
ERROR 2018-08-18 18:03:06,249: 	 Error: crab_plots_PileupAnalyzer_W2 is not a valid CRAB project directory.
ERROR 2018-08-18 18:03:06,249: 	 Caught exception
Traceback (most recent call last):
  File "/cvmfs/cms.cern.ch/crab3/slc6_amd64_gcc493/cms/crabclient/3.3.1805.patch1/bin/crab", line 160, in <module>
    client()
  File "/cvmfs/cms.cern.ch/crab3/slc6_amd64_gcc493/cms/crabclient/3.3.1805.patch1/bin/crab", line 146, in __call__
    self.cmd = sub_cmd(self.logger, args[1:])
  File "/cvmfs/cms.cern.ch/crab3/slc6_amd64_gcc493/cms/crabclient/3.3.1805.patch1/lib/python2.7/site-packages/CRABClient/Commands/status.py", line 39, in __init__
    SubCommand.__init__(self, logger, cmdargs)
  File "/cvmfs/cms.cern.ch/crab3/slc6_amd64_gcc493/cms/crabclient/3.3.1805.patch1/lib/python2.7/site-packages/CRABClient/Commands/SubCommand.py", line 262, in __init__
    self.validateOptions()
  File "/cvmfs/cms.cern.ch/crab3/slc6_amd64_gcc493/cms/crabclient/3.3.1805.patch1/lib/python2.7/site-packages/CRABClient/Commands/status.py", line 1019, in validateOptions
    SubCommand.validateOptions(self)
  File "/cvmfs/cms.cern.ch/crab3/slc6_amd64_gcc493/cms/crabclient/3.3.1805.patch1/lib/python2.7/site-packages/CRABClient/Commands/SubCommand.py", line 575, in validateOptions
    raise ConfigurationException(msg)
ConfigurationException: [91mError[0m: crab_plots_PileupAnalyzer_W2 is not a valid CRAB project directory.
DEBUG 2018-08-18 18:03:06,720: 	 Executing command: 'status'
DEBUG 2018-08-18 18:03:06,720: 	 Found CRAB cache file /afs/cern.ch/user/p/psiddire/.crab3
ERROR 2018-08-18 18:03:06,721: 	 Error: crab_plots_PileupAnalyzer_ttH is not a valid CRAB project directory.
ERROR 2018-08-18 18:03:06,721: 	 Caught exception
Traceback (most recent call last):
  File "/cvmfs/cms.cern.ch/crab3/slc6_amd64_gcc493/cms/crabclient/3.3.1805.patch1/bin/crab", line 160, in <module>
    client()
  File "/cvmfs/cms.cern.ch/crab3/slc6_amd64_gcc493/cms/crabclient/3.3.1805.patch1/bin/crab", line 146, in __call__
    self.cmd = sub_cmd(self.logger, args[1:])
  File "/cvmfs/cms.cern.ch/crab3/slc6_amd64_gcc493/cms/crabclient/3.3.1805.patch1/lib/python2.7/site-packages/CRABClient/Commands/status.py", line 39, in __init__
    SubCommand.__init__(self, logger, cmdargs)
  File "/cvmfs/cms.cern.ch/crab3/slc6_amd64_gcc493/cms/crabclient/3.3.1805.patch1/lib/python2.7/site-packages/CRABClient/Commands/SubCommand.py", line 262, in __init__
    self.validateOptions()
  File "/cvmfs/cms.cern.ch/crab3/slc6_amd64_gcc493/cms/crabclient/3.3.1805.patch1/lib/python2.7/site-packages/CRABClient/Commands/status.py", line 1019, in validateOptions
    SubCommand.validateOptions(self)
  File "/cvmfs/cms.cern.ch/crab3/slc6_amd64_gcc493/cms/crabclient/3.3.1805.patch1/lib/python2.7/site-packages/CRABClient/Commands/SubCommand.py", line 575, in validateOptions
    raise ConfigurationException(msg)
ConfigurationException: [91mError[0m: crab_plots_PileupAnalyzer_ttH is not a valid CRAB project directory.
DEBUG 2018-08-18 18:03:07,202: 	 Executing command: 'status'
DEBUG 2018-08-18 18:03:07,203: 	 Found CRAB cache file /afs/cern.ch/user/p/psiddire/.crab3
ERROR 2018-08-18 18:03:07,203: 	 Error: crab_plots_PileupAnalyzer_STtWat is not a valid CRAB project directory.
ERROR 2018-08-18 18:03:07,203: 	 Caught exception
Traceback (most recent call last):
  File "/cvmfs/cms.cern.ch/crab3/slc6_amd64_gcc493/cms/crabclient/3.3.1805.patch1/bin/crab", line 160, in <module>
    client()
  File "/cvmfs/cms.cern.ch/crab3/slc6_amd64_gcc493/cms/crabclient/3.3.1805.patch1/bin/crab", line 146, in __call__
    self.cmd = sub_cmd(self.logger, args[1:])
  File "/cvmfs/cms.cern.ch/crab3/slc6_amd64_gcc493/cms/crabclient/3.3.1805.patch1/lib/python2.7/site-packages/CRABClient/Commands/status.py", line 39, in __init__
    SubCommand.__init__(self, logger, cmdargs)
  File "/cvmfs/cms.cern.ch/crab3/slc6_amd64_gcc493/cms/crabclient/3.3.1805.patch1/lib/python2.7/site-packages/CRABClient/Commands/SubCommand.py", line 262, in __init__
    self.validateOptions()
  File "/cvmfs/cms.cern.ch/crab3/slc6_amd64_gcc493/cms/crabclient/3.3.1805.patch1/lib/python2.7/site-packages/CRABClient/Commands/status.py", line 1019, in validateOptions
    SubCommand.validateOptions(self)
  File "/cvmfs/cms.cern.ch/crab3/slc6_amd64_gcc493/cms/crabclient/3.3.1805.patch1/lib/python2.7/site-packages/CRABClient/Commands/SubCommand.py", line 575, in validateOptions
    raise ConfigurationException(msg)
ConfigurationException: [91mError[0m: crab_plots_PileupAnalyzer_STtWat is not a valid CRAB project directory.
DEBUG 2018-08-18 18:03:07,644: 	 Executing command: 'status'
DEBUG 2018-08-18 18:03:07,644: 	 Found CRAB cache file /afs/cern.ch/user/p/psiddire/.crab3
ERROR 2018-08-18 18:03:07,645: 	 Error: crab_plots_PileupAnalyzer_W3 is not a valid CRAB project directory.
ERROR 2018-08-18 18:03:07,645: 	 Caught exception
Traceback (most recent call last):
  File "/cvmfs/cms.cern.ch/crab3/slc6_amd64_gcc493/cms/crabclient/3.3.1805.patch1/bin/crab", line 160, in <module>
    client()
  File "/cvmfs/cms.cern.ch/crab3/slc6_amd64_gcc493/cms/crabclient/3.3.1805.patch1/bin/crab", line 146, in __call__
    self.cmd = sub_cmd(self.logger, args[1:])
  File "/cvmfs/cms.cern.ch/crab3/slc6_amd64_gcc493/cms/crabclient/3.3.1805.patch1/lib/python2.7/site-packages/CRABClient/Commands/status.py", line 39, in __init__
    SubCommand.__init__(self, logger, cmdargs)
  File "/cvmfs/cms.cern.ch/crab3/slc6_amd64_gcc493/cms/crabclient/3.3.1805.patch1/lib/python2.7/site-packages/CRABClient/Commands/SubCommand.py", line 262, in __init__
    self.validateOptions()
  File "/cvmfs/cms.cern.ch/crab3/slc6_amd64_gcc493/cms/crabclient/3.3.1805.patch1/lib/python2.7/site-packages/CRABClient/Commands/status.py", line 1019, in validateOptions
    SubCommand.validateOptions(self)
  File "/cvmfs/cms.cern.ch/crab3/slc6_amd64_gcc493/cms/crabclient/3.3.1805.patch1/lib/python2.7/site-packages/CRABClient/Commands/SubCommand.py", line 575, in validateOptions
    raise ConfigurationException(msg)
ConfigurationException: [91mError[0m: crab_plots_PileupAnalyzer_W3 is not a valid CRAB project directory.
DEBUG 2018-09-08 20:14:32,698: 	 Executing command: 'submit'
DEBUG 2018-09-08 20:14:32,698: 	 Found CRAB cache file /afs/cern.ch/user/p/psiddire/.crab3
DEBUG 2018-10-09 18:09:12,636: 	 Executing command: 'submit'
DEBUG 2018-10-09 18:09:12,636: 	 Found CRAB cache file /afs/cern.ch/user/p/psiddire/.crab3
DEBUG 2018-10-09 18:09:12,644: 	 Checking credentials
DEBUG 2018-10-09 18:09:12,646: 	 Found proxy file /tmp/x509up_u93494
DEBUG 2018-10-09 18:09:12,647: 	 Getting proxy life time left
DEBUG 2018-10-09 18:09:13,352: 	 Executing : 
 command : voms-proxy-info -file /tmp/x509up_u93494 -timeleft
 output : 41780

 error: 
 retcode : 0
DEBUG 2018-10-09 18:09:13,957: 	 Executing : 
 command : voms-proxy-info -file /tmp/x509up_u93494 -actimeleft
 output : 41780

 error: 
 retcode : 0
DEBUG 2018-10-09 18:09:13,957: 	 Proxy valid for 11:36:20 hours
INFO 2018-10-09 18:09:13,957: 	 Will use CRAB configuration file crab_DY10ext1v1.py
DEBUG 2018-10-09 18:09:13,957: 	 Loading CRAB configuration file.
DEBUG 2018-10-09 18:09:18,344: 	 Will use CRAB Analysis plugin (i.e. will run an analysis job type).
ERROR 2018-10-09 18:09:18,344: 	 Working area '/afs/cern.ch/user/p/psiddire/CMSSW_9_4_8/src/pileup/PileupAnalyzer/test/crab_projects/crab_plots_PileupAnalyzer_DY10ext1v1' already exists 
Please change the requestName in the config file
ERROR 2018-10-09 18:09:18,344: 	 Caught exception
Traceback (most recent call last):
  File "/cvmfs/cms.cern.ch/crab3/slc6_amd64_gcc493/cms/crabclient/3.3.1809-comp/bin/crab", line 160, in <module>
    client()
  File "/cvmfs/cms.cern.ch/crab3/slc6_amd64_gcc493/cms/crabclient/3.3.1809-comp/bin/crab", line 146, in __call__
    self.cmd = sub_cmd(self.logger, args[1:])
  File "/cvmfs/cms.cern.ch/crab3/slc6_amd64_gcc493/cms/crabclient/3.3.1809-comp/lib/python2.7/site-packages/CRABClient/Commands/submit.py", line 34, in __init__
    SubCommand.__init__(self, logger, cmdargs, disable_interspersed_args=True)
  File "/cvmfs/cms.cern.ch/crab3/slc6_amd64_gcc493/cms/crabclient/3.3.1809-comp/lib/python2.7/site-packages/CRABClient/Commands/SubCommand.py", line 307, in __init__
    getattr(self.configuration.General, 'requestName', None))
  File "/cvmfs/cms.cern.ch/crab3/slc6_amd64_gcc493/cms/crabclient/3.3.1809-comp/lib/python2.7/site-packages/CRABClient/ClientUtilities.py", line 404, in createWorkArea
    raise ConfigException("Working area '%s' already exists \nPlease change the requestName in the config file" % fullpath)
ConfigException: Working area '/afs/cern.ch/user/p/psiddire/CMSSW_9_4_8/src/pileup/PileupAnalyzer/test/crab_projects/crab_plots_PileupAnalyzer_DY10ext1v1' already exists 
Please change the requestName in the config file
DEBUG 2019-02-21 12:02:31,023: 	 Executing command: 'status'
DEBUG 2019-02-21 12:02:31,027: 	 Found CRAB cache file /afs/cern.ch/user/p/psiddire/.crab3
ERROR 2019-02-21 12:02:31,031: 	 Cannot find .requestcache file in CRAB project directory /afs/cern.ch/user/p/psiddire/CMSSW_9_4_8/src/pileup/PileupAnalyzer/test/crab_projects/crab_plots_PileupAnalyzer_WWW/results
ERROR 2019-02-21 12:02:31,031: 	 Caught exception
Traceback (most recent call last):
  File "/cvmfs/cms.cern.ch/crab3/slc6_amd64_gcc493/cms/crabclient/3.3.1902.patch1/bin/crab", line 160, in <module>
    client()
  File "/cvmfs/cms.cern.ch/crab3/slc6_amd64_gcc493/cms/crabclient/3.3.1902.patch1/bin/crab", line 146, in __call__
    self.cmd = sub_cmd(self.logger, args[1:])
  File "/cvmfs/cms.cern.ch/crab3/slc6_amd64_gcc493/cms/crabclient/3.3.1902.patch1/lib/python2.7/site-packages/CRABClient/Commands/status.py", line 40, in __init__
    SubCommand.__init__(self, logger, cmdargs)
  File "/cvmfs/cms.cern.ch/crab3/slc6_amd64_gcc493/cms/crabclient/3.3.1902.patch1/lib/python2.7/site-packages/CRABClient/Commands/SubCommand.py", line 266, in __init__
    SubCommand.validateOptions(self)
  File "/cvmfs/cms.cern.ch/crab3/slc6_amd64_gcc493/cms/crabclient/3.3.1902.patch1/lib/python2.7/site-packages/CRABClient/Commands/SubCommand.py", line 588, in validateOptions
    self.loadLocalCache()
  File "/cvmfs/cms.cern.ch/crab3/slc6_amd64_gcc493/cms/crabclient/3.3.1902.patch1/lib/python2.7/site-packages/CRABClient/Commands/SubCommand.py", line 450, in loadLocalCache
    raise ex
CachefileNotFoundException: Cannot find .requestcache file in CRAB project directory /afs/cern.ch/user/p/psiddire/CMSSW_9_4_8/src/pileup/PileupAnalyzer/test/crab_projects/crab_plots_PileupAnalyzer_WWW/results
DEBUG 2019-03-05 22:05:53,627: 	 Executing command: 'status'
DEBUG 2019-03-05 22:05:53,628: 	 Found CRAB cache file /afs/cern.ch/user/p/psiddire/.crab3
DEBUG 2019-03-05 22:05:54,429: 	 Executing command: 'status'
DEBUG 2019-03-05 22:05:54,430: 	 Found CRAB cache file /afs/cern.ch/user/p/psiddire/.crab3
DEBUG 2019-03-05 22:05:55,154: 	 Executing command: 'status'
DEBUG 2019-03-05 22:05:55,154: 	 Found CRAB cache file /afs/cern.ch/user/p/psiddire/.crab3
DEBUG 2019-03-05 22:05:55,845: 	 Executing command: 'status'
DEBUG 2019-03-05 22:05:55,845: 	 Found CRAB cache file /afs/cern.ch/user/p/psiddire/.crab3
DEBUG 2019-03-05 22:05:56,521: 	 Executing command: 'status'
DEBUG 2019-03-05 22:05:56,522: 	 Found CRAB cache file /afs/cern.ch/user/p/psiddire/.crab3
DEBUG 2019-03-05 22:22:06,465: 	 Executing command: 'submit'
DEBUG 2019-03-05 22:22:06,466: 	 Found CRAB cache file /afs/cern.ch/user/p/psiddire/.crab3
DEBUG 2019-03-05 22:22:06,478: 	 Checking credentials
DEBUG 2019-03-05 22:22:06,480: 	 Found proxy file /tmp/x509up_u93494
DEBUG 2019-03-05 22:22:06,480: 	 Getting proxy life time left
DEBUG 2019-03-05 22:22:07,801: 	 Executing : 
 command : voms-proxy-info -file /tmp/x509up_u93494 -timeleft
 output : 690215

 error: 
 retcode : 0
DEBUG 2019-03-05 22:22:08,928: 	 Executing : 
 command : voms-proxy-info -file /tmp/x509up_u93494 -actimeleft
 output : 690214

 error: 
 retcode : 0
DEBUG 2019-03-05 22:22:08,929: 	 Proxy lifetime 690215 secs is different from voms extension lifetime 690214 secs for proxy: /tmp/x509up_u93494
DEBUG 2019-03-05 22:22:08,929: 	 Proxy valid for 191:43:34 hours
INFO 2019-03-05 22:22:08,930: 	 Will use CRAB configuration file crab_EWKWplus.py
DEBUG 2019-03-05 22:22:08,931: 	 Loading CRAB configuration file.
ERROR 2019-03-05 22:22:12,720: 	 Invalid CRAB configuration: Parameter Data.allowNonValidInputDataset requires a value of type <type 'bool'> (while a value of type <type 'str'> was given).
The documentation about the CRAB configuration file can be found in https://twiki.cern.ch/twiki/bin/view/CMSPublic/CRAB3ConfigurationFile
ERROR 2019-03-05 22:22:12,720: 	 Caught exception
Traceback (most recent call last):
  File "/cvmfs/cms.cern.ch/crab3/slc6_amd64_gcc493/cms/crabclient/3.3.1902.patch1/bin/crab", line 160, in <module>
    client()
  File "/cvmfs/cms.cern.ch/crab3/slc6_amd64_gcc493/cms/crabclient/3.3.1902.patch1/bin/crab", line 146, in __call__
    self.cmd = sub_cmd(self.logger, args[1:])
  File "/cvmfs/cms.cern.ch/crab3/slc6_amd64_gcc493/cms/crabclient/3.3.1902.patch1/lib/python2.7/site-packages/CRABClient/Commands/submit.py", line 34, in __init__
    SubCommand.__init__(self, logger, cmdargs, disable_interspersed_args=True)
  File "/cvmfs/cms.cern.ch/crab3/slc6_amd64_gcc493/cms/crabclient/3.3.1902.patch1/lib/python2.7/site-packages/CRABClient/Commands/SubCommand.py", line 309, in __init__
    self.loadConfig(self.options.config, self.args)
  File "/cvmfs/cms.cern.ch/crab3/slc6_amd64_gcc493/cms/crabclient/3.3.1902.patch1/lib/python2.7/site-packages/CRABClient/Commands/SubCommand.py", line 92, in loadConfig
    raise ConfigurationException(configmsg)
ConfigurationException: Invalid CRAB configuration: Parameter Data.allowNonValidInputDataset requires a value of type <type 'bool'> (while a value of type <type 'str'> was given).
The documentation about the CRAB configuration file can be found in https://twiki.cern.ch/twiki/bin/view/CMSPublic/CRAB3ConfigurationFile
